<?xml version="1.0"?>
<robot name="my_bot">
        <material name="green">
            <color rgba="0 1 0 1"/>
        </material>
        <material name="gray">
            <color rgba="1 0 0 1"/>
        </material>
        <link name="base_foot"/>  
    <joint name="base" type="fixed">
       <parent link="base_foot"/>
       <child link="base_link"/>
       <origin xyz="0 0 0.2" rpy="0 0 0"/>
    </joint>    
        <link name="base_link">
            <visual>
                <geometry>
                    <box size="0.6 0.4 0.2"/>
                </geometry>
                <origin xyz="0 0 0" rpy="0 0 0"/>
                <material name="green"/>
            </visual>
        </link>
      
        <link name="right_link">
            <visual>
                <geometry>
                    <cylinder radius="0.1" length="0.05"/>
                </geometry>
                <origin xyz="0 0 0" rpy="1.57 0 0"/>
                <material name ="gray"/>
            </visual>
        </link>
    <joint name="right_joint" type="continuous">
        <parent link="base_link"/>
        <child link="right_link"/>
        <origin xyz="-0.1 -0.225 -0.1" rpy="0 0 0"/>
        <axis xyz="0 1 0"/>
    </joint>
        <link name="left_link">
            <visual>
                <geometry>
                    <cylinder radius="0.1" length="0.05"/>
                </geometry>
                <origin xyz="0 0 0" rpy="1.57 0 0"/>
                <material name="gray"/>
            </visual>
        </link>  
    <joint name="left_joint" type="continuous">
       <parent link="base_link"/>
       <child link ="left_link"/>
       <origin xyz="-0.1 0.225 -0.1" rpy="0 0 0"/>
       <axis xyz="0 1 0"/>
    </joint>
        <link name="caster_wheel">
            <visual>
                <geometry>
                    <sphere radius="0.05"/>
                </geometry>
                <origin xyz="0 0 0" rpy="0 0 0"/>
                <material name="gray"/>
            </visual>
        </link>
    <joint name="caster joint" type="continuous"> 
        <parent link="base_link"/>
        <child link="caster_wheel"/>
        <origin xyz="0.2 0 -0.15" rpy="0 0 0"/>
        <axis xyz="1 1 1"/>
    </joint>
    <joint name="lider_base" type="revolute">
        <parent link="base_link"/>
        <child link="lider_link"/>
        <origin xyz="0 0 0.125" rpy="0 0 0"/>
        <axis xyz="0 0 1"/>
        <limit lower="-3.14" upper="3.14" velocity="100" effort="100"/>

    </joint>
       <link name="lider_link">
            <visual>
                <geometry>
                    <cylinder radius="0.1" length="0.06"/>
                </geometry>
                <origin xyz="0 0 0" rpy="0 0 0"/>
                <material name="gray"/>
            </visual>
       </link>

</robot>
